2023-01-26 10:00:51,360 [INFO] 22080 21456 D:\Anaconda3\lib\site-packages\django\utils\autoreload.py:677 Watching for file changes with StatReloader
2023-01-26 10:00:58,260 [INFO] 22080 2828 D:\Anaconda3\lib\site-packages\django\core\servers\basehttp.py:187 "GET /hp_admin/ HTTP/1.1" 200 5170
2023-01-26 10:01:14,627 [INFO] 22080 2828 D:\Anaconda3\lib\site-packages\django\core\servers\basehttp.py:187 "GET /hp/company HTTP/1.1" 200 13
2023-01-26 10:02:29,598 [INFO] 22080 21456 D:\Anaconda3\lib\site-packages\django\utils\autoreload.py:266 D:\vscode\hp_admin\hp\views.py changed, reloading.
2023-01-26 10:02:30,178 [INFO] 9760 13976 D:\Anaconda3\lib\site-packages\django\utils\autoreload.py:677 Watching for file changes with StatReloader
2023-01-26 10:02:32,482 [INFO] 9760 13976 D:\Anaconda3\lib\site-packages\django\utils\autoreload.py:266 D:\vscode\hp_admin\hp\views.py changed, reloading.
2023-01-26 10:02:33,060 [INFO] 18600 23232 D:\Anaconda3\lib\site-packages\django\utils\autoreload.py:677 Watching for file changes with StatReloader
2023-01-26 10:02:51,840 [INFO] 18600 23232 D:\Anaconda3\lib\site-packages\django\utils\autoreload.py:266 D:\vscode\hp_admin\hp\views.py changed, reloading.
2023-01-26 10:02:52,416 [INFO] 7972 5660 D:\Anaconda3\lib\site-packages\django\utils\autoreload.py:677 Watching for file changes with StatReloader
2023-01-26 10:03:09,188 [INFO] 7972 5660 D:\Anaconda3\lib\site-packages\django\utils\autoreload.py:266 D:\vscode\hp_admin\hp\views.py changed, reloading.
2023-01-26 10:03:09,761 [INFO] 12204 23620 D:\Anaconda3\lib\site-packages\django\utils\autoreload.py:677 Watching for file changes with StatReloader
2023-01-26 10:03:37,947 [INFO] 12204 23620 D:\Anaconda3\lib\site-packages\django\utils\autoreload.py:266 D:\vscode\hp_admin\hp\views.py changed, reloading.
2023-01-26 10:03:38,542 [INFO] 19408 16196 D:\Anaconda3\lib\site-packages\django\utils\autoreload.py:677 Watching for file changes with StatReloader
2023-01-26 10:03:57,328 [INFO] 19408 16196 D:\Anaconda3\lib\site-packages\django\utils\autoreload.py:266 D:\vscode\hp_admin\hp\views.py changed, reloading.
2023-01-26 10:03:57,918 [INFO] 13744 14724 D:\Anaconda3\lib\site-packages\django\utils\autoreload.py:677 Watching for file changes with StatReloader
2023-01-26 10:04:07,470 [INFO] 13744 14724 D:\Anaconda3\lib\site-packages\django\utils\autoreload.py:266 D:\vscode\hp_admin\hp\views.py changed, reloading.
2023-01-26 10:04:08,060 [INFO] 13352 9612 D:\Anaconda3\lib\site-packages\django\utils\autoreload.py:677 Watching for file changes with StatReloader
2023-01-26 10:04:10,815 [ERROR] 13352 6648 D:\Anaconda3\lib\site-packages\django\utils\log.py:241 Internal Server Error: /hp/company
Traceback (most recent call last):
  File "D:\Anaconda3\lib\site-packages\django\core\handlers\exception.py", line 55, in inner
    response = get_response(request)
  File "D:\Anaconda3\lib\site-packages\django\core\handlers\base.py", line 197, in _get_response
    response = wrapped_callback(request, *callback_args, **callback_kwargs)
  File "D:\Anaconda3\lib\site-packages\django\views\generic\base.py", line 103, in view
    return self.dispatch(request, *args, **kwargs)
  File "D:\Anaconda3\lib\site-packages\django\views\generic\base.py", line 142, in dispatch
    return handler(request, *args, **kwargs)
  File "d:\vscode\hp_admin\hp\views.py", line 31, in get
    return JsonResponse(params)
  File "D:\Anaconda3\lib\site-packages\django\http\response.py", line 691, in __init__
    data = json.dumps(data, cls=encoder, **json_dumps_params)
  File "D:\Anaconda3\lib\json\__init__.py", line 234, in dumps
    return cls(
  File "D:\Anaconda3\lib\json\encoder.py", line 199, in encode
    chunks = self.iterencode(o, _one_shot=True)
  File "D:\Anaconda3\lib\json\encoder.py", line 257, in iterencode
    return _iterencode(o, 0)
  File "D:\Anaconda3\lib\site-packages\django\core\serializers\json.py", line 106, in default
    return super().default(o)
  File "D:\Anaconda3\lib\json\encoder.py", line 179, in default
    raise TypeError(f'Object of type {o.__class__.__name__} '
TypeError: Object of type QuerySet is not JSON serializable
2023-01-26 10:04:10,817 [ERROR] 13352 6648 D:\Anaconda3\lib\site-packages\django\core\servers\basehttp.py:187 "GET /hp/company HTTP/1.1" 500 103786
2023-01-26 10:06:04,383 [INFO] 13352 9612 D:\Anaconda3\lib\site-packages\django\utils\autoreload.py:266 D:\vscode\hp_admin\hp\views.py changed, reloading.
2023-01-26 10:06:04,995 [INFO] 24732 21140 D:\Anaconda3\lib\site-packages\django\utils\autoreload.py:677 Watching for file changes with StatReloader
2023-01-26 10:06:16,533 [INFO] 24732 21140 D:\Anaconda3\lib\site-packages\django\utils\autoreload.py:266 D:\vscode\hp_admin\hp\views.py changed, reloading.
2023-01-26 10:06:17,111 [INFO] 23392 17464 D:\Anaconda3\lib\site-packages\django\utils\autoreload.py:677 Watching for file changes with StatReloader
2023-01-26 10:06:21,122 [INFO] 23392 22488 D:\Anaconda3\lib\site-packages\django\core\servers\basehttp.py:187 "GET /hp/company HTTP/1.1" 200 1802
2023-01-26 10:08:08,855 [INFO] 23392 17464 D:\Anaconda3\lib\site-packages\django\utils\autoreload.py:266 D:\vscode\hp_admin\hp\views.py changed, reloading.
2023-01-26 10:08:09,457 [INFO] 5032 6940 D:\Anaconda3\lib\site-packages\django\utils\autoreload.py:677 Watching for file changes with StatReloader
2023-01-26 10:08:32,432 [INFO] 5032 6940 D:\Anaconda3\lib\site-packages\django\utils\autoreload.py:266 D:\vscode\hp_admin\hp\views.py changed, reloading.
2023-01-26 10:08:33,051 [INFO] 18728 15640 D:\Anaconda3\lib\site-packages\django\utils\autoreload.py:677 Watching for file changes with StatReloader
2023-01-26 10:08:39,428 [ERROR] 18728 22784 D:\Anaconda3\lib\site-packages\django\utils\log.py:241 Internal Server Error: /hp/company
Traceback (most recent call last):
  File "D:\Anaconda3\lib\site-packages\django\core\handlers\exception.py", line 55, in inner
    response = get_response(request)
  File "D:\Anaconda3\lib\site-packages\django\core\handlers\base.py", line 197, in _get_response
    response = wrapped_callback(request, *callback_args, **callback_kwargs)
  File "D:\Anaconda3\lib\site-packages\django\views\generic\base.py", line 103, in view
    return self.dispatch(request, *args, **kwargs)
  File "D:\Anaconda3\lib\site-packages\django\views\generic\base.py", line 142, in dispatch
    return handler(request, *args, **kwargs)
  File "d:\vscode\hp_admin\hp\views.py", line 28, in get
    'company': model_to_dict(company)
  File "D:\Anaconda3\lib\site-packages\django\forms\models.py", line 105, in model_to_dict
    opts = instance._meta
AttributeError: 'QuerySet' object has no attribute '_meta'
2023-01-26 10:08:39,429 [ERROR] 18728 22784 D:\Anaconda3\lib\site-packages\django\core\servers\basehttp.py:187 "GET /hp/company HTTP/1.1" 500 82948
2023-01-26 10:10:16,552 [INFO] 18728 15640 D:\Anaconda3\lib\site-packages\django\utils\autoreload.py:266 D:\vscode\hp_admin\hp\views.py changed, reloading.
2023-01-26 10:10:17,120 [INFO] 18612 18920 D:\Anaconda3\lib\site-packages\django\utils\autoreload.py:677 Watching for file changes with StatReloader
2023-01-26 10:10:24,585 [INFO] 18612 18920 D:\Anaconda3\lib\site-packages\django\utils\autoreload.py:266 D:\vscode\hp_admin\hp\views.py changed, reloading.
2023-01-26 10:10:25,165 [INFO] 25220 5240 D:\Anaconda3\lib\site-packages\django\utils\autoreload.py:677 Watching for file changes with StatReloader
2023-01-26 10:10:29,774 [ERROR] 25220 23372 D:\Anaconda3\lib\site-packages\django\utils\log.py:241 Internal Server Error: /hp/company
Traceback (most recent call last):
  File "D:\Anaconda3\lib\site-packages\django\core\handlers\exception.py", line 55, in inner
    response = get_response(request)
  File "D:\Anaconda3\lib\site-packages\django\core\handlers\base.py", line 197, in _get_response
    response = wrapped_callback(request, *callback_args, **callback_kwargs)
  File "D:\Anaconda3\lib\site-packages\django\views\generic\base.py", line 103, in view
    return self.dispatch(request, *args, **kwargs)
  File "D:\Anaconda3\lib\site-packages\django\views\generic\base.py", line 142, in dispatch
    return handler(request, *args, **kwargs)
  File "d:\vscode\hp_admin\hp\views.py", line 29, in get
    'company': json.dumps(model_to_dict(company))
  File "D:\Anaconda3\lib\site-packages\django\forms\models.py", line 105, in model_to_dict
    opts = instance._meta
AttributeError: 'QuerySet' object has no attribute '_meta'
2023-01-26 10:10:29,776 [ERROR] 25220 23372 D:\Anaconda3\lib\site-packages\django\core\servers\basehttp.py:187 "GET /hp/company HTTP/1.1" 500 82972
2023-01-26 10:14:31,431 [INFO] 25220 5240 D:\Anaconda3\lib\site-packages\django\utils\autoreload.py:266 D:\vscode\hp_admin\hp\views.py changed, reloading.
2023-01-26 10:14:32,020 [INFO] 14376 14384 D:\Anaconda3\lib\site-packages\django\utils\autoreload.py:677 Watching for file changes with StatReloader
2023-01-26 10:15:16,645 [INFO] 14376 14384 D:\Anaconda3\lib\site-packages\django\utils\autoreload.py:266 D:\vscode\hp_admin\hp\views.py changed, reloading.
2023-01-26 10:15:17,224 [INFO] 360 3316 D:\Anaconda3\lib\site-packages\django\utils\autoreload.py:677 Watching for file changes with StatReloader
2023-01-26 10:15:20,557 [INFO] 360 3316 D:\Anaconda3\lib\site-packages\django\utils\autoreload.py:266 D:\vscode\hp_admin\hp\views.py changed, reloading.
2023-01-26 10:15:21,118 [INFO] 9888 9476 D:\Anaconda3\lib\site-packages\django\utils\autoreload.py:677 Watching for file changes with StatReloader
2023-01-26 10:15:27,838 [ERROR] 9888 13372 D:\Anaconda3\lib\site-packages\django\utils\log.py:241 Internal Server Error: /hp/company
Traceback (most recent call last):
  File "D:\Anaconda3\lib\site-packages\django\core\handlers\exception.py", line 55, in inner
    response = get_response(request)
  File "D:\Anaconda3\lib\site-packages\django\core\handlers\base.py", line 197, in _get_response
    response = wrapped_callback(request, *callback_args, **callback_kwargs)
  File "D:\Anaconda3\lib\site-packages\django\views\generic\base.py", line 103, in view
    return self.dispatch(request, *args, **kwargs)
  File "D:\Anaconda3\lib\site-packages\django\views\generic\base.py", line 142, in dispatch
    return handler(request, *args, **kwargs)
  File "d:\vscode\hp_admin\hp\views.py", line 33, in get
    return JsonResponse(serializers.serialize('json', params))
  File "D:\Anaconda3\lib\site-packages\django\core\serializers\__init__.py", line 134, in serialize
    s.serialize(queryset, **options)
  File "D:\Anaconda3\lib\site-packages\django\core\serializers\base.py", line 136, in serialize
    concrete_model = obj._meta.concrete_model
AttributeError: 'str' object has no attribute '_meta'
2023-01-26 10:15:27,840 [ERROR] 9888 13372 D:\Anaconda3\lib\site-packages\django\core\servers\basehttp.py:187 "GET /hp/company HTTP/1.1" 500 88560
2023-01-26 10:15:35,497 [ERROR] 9888 13372 D:\Anaconda3\lib\site-packages\django\utils\log.py:241 Internal Server Error: /hp/company
Traceback (most recent call last):
  File "D:\Anaconda3\lib\site-packages\django\core\handlers\exception.py", line 55, in inner
    response = get_response(request)
  File "D:\Anaconda3\lib\site-packages\django\core\handlers\base.py", line 197, in _get_response
    response = wrapped_callback(request, *callback_args, **callback_kwargs)
  File "D:\Anaconda3\lib\site-packages\django\views\generic\base.py", line 103, in view
    return self.dispatch(request, *args, **kwargs)
  File "D:\Anaconda3\lib\site-packages\django\views\generic\base.py", line 142, in dispatch
    return handler(request, *args, **kwargs)
  File "d:\vscode\hp_admin\hp\views.py", line 33, in get
    return JsonResponse(serializers.serialize('json', params))
  File "D:\Anaconda3\lib\site-packages\django\core\serializers\__init__.py", line 134, in serialize
    s.serialize(queryset, **options)
  File "D:\Anaconda3\lib\site-packages\django\core\serializers\base.py", line 136, in serialize
    concrete_model = obj._meta.concrete_model
AttributeError: 'str' object has no attribute '_meta'
2023-01-26 10:15:35,498 [ERROR] 9888 13372 D:\Anaconda3\lib\site-packages\django\core\servers\basehttp.py:187 "GET /hp/company HTTP/1.1" 500 88560
2023-01-26 10:16:02,781 [INFO] 9888 9476 D:\Anaconda3\lib\site-packages\django\utils\autoreload.py:266 D:\vscode\hp_admin\hp\views.py changed, reloading.
2023-01-26 10:16:03,376 [INFO] 10664 15948 D:\Anaconda3\lib\site-packages\django\utils\autoreload.py:677 Watching for file changes with StatReloader
2023-01-26 10:16:06,758 [INFO] 10664 20692 D:\Anaconda3\lib\site-packages\django\core\servers\basehttp.py:187 "GET /hp/company HTTP/1.1" 200 1802
2023-01-26 10:17:05,601 [INFO] 10664 15948 D:\Anaconda3\lib\site-packages\django\utils\autoreload.py:266 D:\vscode\hp_admin\hp\views.py changed, reloading.
2023-01-26 10:17:06,184 [INFO] 10116 20156 D:\Anaconda3\lib\site-packages\django\utils\autoreload.py:677 Watching for file changes with StatReloader
2023-01-26 10:17:12,224 [INFO] 10116 12388 D:\Anaconda3\lib\site-packages\django\core\servers\basehttp.py:187 "GET /hp/company HTTP/1.1" 200 1802
2023-01-26 10:20:28,545 [INFO] 10116 20156 D:\Anaconda3\lib\site-packages\django\utils\autoreload.py:266 D:\vscode\hp_admin\hp\views.py changed, reloading.
2023-01-26 10:20:29,134 [INFO] 1452 18728 D:\Anaconda3\lib\site-packages\django\utils\autoreload.py:677 Watching for file changes with StatReloader
2023-01-26 10:20:38,430 [ERROR] 1452 18912 D:\Anaconda3\lib\site-packages\django\utils\log.py:241 Internal Server Error: /hp/company
Traceback (most recent call last):
  File "D:\Anaconda3\lib\site-packages\django\core\handlers\exception.py", line 55, in inner
    response = get_response(request)
  File "D:\Anaconda3\lib\site-packages\django\core\handlers\base.py", line 197, in _get_response
    response = wrapped_callback(request, *callback_args, **callback_kwargs)
  File "D:\Anaconda3\lib\site-packages\django\views\generic\base.py", line 103, in view
    return self.dispatch(request, *args, **kwargs)
  File "D:\Anaconda3\lib\site-packages\django\views\generic\base.py", line 142, in dispatch
    return handler(request, *args, **kwargs)
  File "d:\vscode\hp_admin\hp\views.py", line 30, in get
    'company': serializers.serialize('json', company)
  File "D:\Anaconda3\lib\site-packages\django\core\serializers\__init__.py", line 134, in serialize
    s.serialize(queryset, **options)
  File "D:\Anaconda3\lib\site-packages\django\core\serializers\base.py", line 136, in serialize
    concrete_model = obj._meta.concrete_model
AttributeError: 'dict' object has no attribute '_meta'
2023-01-26 10:20:38,432 [ERROR] 1452 18912 D:\Anaconda3\lib\site-packages\django\core\servers\basehttp.py:187 "GET /hp/company HTTP/1.1" 500 93795
2023-01-26 10:22:15,204 [INFO] 1452 18728 D:\Anaconda3\lib\site-packages\django\utils\autoreload.py:266 D:\vscode\hp_admin\hp\views.py changed, reloading.
2023-01-26 10:22:15,817 [INFO] 3848 25544 D:\Anaconda3\lib\site-packages\django\utils\autoreload.py:677 Watching for file changes with StatReloader
2023-01-26 10:22:19,238 [ERROR] 3848 24732 D:\Anaconda3\lib\site-packages\django\utils\log.py:241 Internal Server Error: /hp/company
Traceback (most recent call last):
  File "D:\Anaconda3\lib\site-packages\django\core\handlers\exception.py", line 55, in inner
    response = get_response(request)
  File "D:\Anaconda3\lib\site-packages\django\core\handlers\base.py", line 197, in _get_response
    response = wrapped_callback(request, *callback_args, **callback_kwargs)
  File "D:\Anaconda3\lib\site-packages\django\views\generic\base.py", line 103, in view
    return self.dispatch(request, *args, **kwargs)
  File "D:\Anaconda3\lib\site-packages\django\views\generic\base.py", line 142, in dispatch
    return handler(request, *args, **kwargs)
  File "d:\vscode\hp_admin\hp\views.py", line 34, in get
    return JsonResponse(params)
  File "D:\Anaconda3\lib\site-packages\django\http\response.py", line 691, in __init__
    data = json.dumps(data, cls=encoder, **json_dumps_params)
  File "D:\Anaconda3\lib\json\__init__.py", line 234, in dumps
    return cls(
  File "D:\Anaconda3\lib\json\encoder.py", line 199, in encode
    chunks = self.iterencode(o, _one_shot=True)
  File "D:\Anaconda3\lib\json\encoder.py", line 257, in iterencode
    return _iterencode(o, 0)
  File "D:\Anaconda3\lib\site-packages\django\core\serializers\json.py", line 106, in default
    return super().default(o)
  File "D:\Anaconda3\lib\json\encoder.py", line 179, in default
    raise TypeError(f'Object of type {o.__class__.__name__} '
TypeError: Object of type QuerySet is not JSON serializable
2023-01-26 10:22:19,240 [ERROR] 3848 24732 D:\Anaconda3\lib\site-packages\django\core\servers\basehttp.py:187 "GET /hp/company HTTP/1.1" 500 115698
2023-01-26 10:25:34,892 [INFO] 3848 25544 D:\Anaconda3\lib\site-packages\django\utils\autoreload.py:266 D:\vscode\hp_admin\hp\views.py changed, reloading.
2023-01-26 10:25:35,528 [INFO] 23092 19192 D:\Anaconda3\lib\site-packages\django\utils\autoreload.py:677 Watching for file changes with StatReloader
2023-01-26 10:25:38,828 [INFO] 23092 11088 D:\Anaconda3\lib\site-packages\django\core\servers\basehttp.py:187 "GET /hp/company HTTP/1.1" 200 1701
2023-01-26 10:26:01,715 [INFO] 23092 19192 D:\Anaconda3\lib\site-packages\django\utils\autoreload.py:266 D:\vscode\hp_admin\hp\views.py changed, reloading.
2023-01-26 10:26:02,353 [INFO] 23372 5240 D:\Anaconda3\lib\site-packages\django\utils\autoreload.py:677 Watching for file changes with StatReloader
2023-01-26 10:26:04,436 [INFO] 23372 12884 D:\Anaconda3\lib\site-packages\django\core\servers\basehttp.py:187 "GET /hp/company HTTP/1.1" 200 1701
